Workbook

Sheet Dashboard
A1: Loyalty & PLCC Emails Dashboard
A2: This dashboard auto-summarizes Jira tickets sourced from the Project Tracker.
A4: Total Projects | B4: In Progress | C4: Completed | D4: Upcoming | E4: Cancelled
A5: =COUNTIF('Project Tracker'!$B$2:$B$201,"<>") -> 12 | B5: =COUNTIFS('Project Tracker'!$C$2:$C$201,"In Progress",'Project Tracker'!$B$2:$B$201,"<>") -> 4 | C5: =COUNTIFS('Project Tracker'!$C$2:$C$201,"Completed",'Project Tracker'!$B$2:$B$201,"<>") -> 2 | D5: =COUNTIFS('Project Tracker'!$C$2:$C$201,"Upcoming",'Project Tracker'!$B$2:$B$201,"<>") -> 3 | E5: =COUNTIFS('Project Tracker'!$C$2:$C$201,"Cancelled",'Project Tracker'!$B$2:$B$201,"<>") -> 3
A7: Status | B7: Count | D7: Send Date Summary
A8: Upcoming | B8: =COUNTIFS('Project Tracker'!$C$2:$C$201,A8,'Project Tracker'!$B$2:$B$201,"<>") -> 3 | D8: Metric | E8: Value
A9: In Progress | B9: =COUNTIFS('Project Tracker'!$C$2:$C$201,A9,'Project Tracker'!$B$2:$B$201,"<>") -> 4 | D9: Sends Jan-Dec 2027 | E9: =COUNTIFS('Project Tracker'!$D$2:$D$201,">="&DATE(2027,1,1),'Project Tracker'!$D$2:$D$201,"<="&DATE(2027,12,31),'Project Tracker'!$B$2:$B$201,"<>") -> 6
A10: Completed | B10: =COUNTIFS('Project Tracker'!$C$2:$C$201,A10,'Project Tracker'!$B$2:$B$201,"<>") -> 2 | D10: Active Sends Next 14 Days | E10: =COUNTIFS('Project Tracker'!$D$2:$D$201,">="&TODAY(),'Project Tracker'!$D$2:$D$201,"<="&TODAY()+14,'Project Tracker'!$C$2:$C$201,"<>Completed",'Project Tracker'!$C$2:$C$201,"<>Cancelled",'Project Tracker'!$B$2:$B$201,"<>") -> 1
A11: Cancelled | B11: =COUNTIFS('Project Tracker'!$C$2:$C$201,A11,'Project Tracker'!$B$2:$B$201,"<>") -> 3 | D11: Next Send Date | E11: =IF(MIN('Project Tracker'!$H$2:$H$201)>999999,"",MIN('Project Tracker'!$H$2:$H$201)) -> 46210
D12: Next Jira Ticket | E12: =IFERROR(INDEX('Project Tracker'!$A$2:$A$201,MATCH($E$11,'Project Tracker'!$H$2:$H$201,0)),"") -> JIRA-1007
D13: Next Project | E13: =IFERROR(INDEX('Project Tracker'!$B$2:$B$201,MATCH($E$11,'Project Tracker'!$H$2:$H$201,0)),"") -> TEST
D16: Note: Please update or modify Jira tickets within the Project Tracker sheet. The calendar worksheets utilize the Send Date to extract and display campaign names for specific dates.

Sheet Project Tracker
A1: Jira Ticket Link | B1: Campaign | C1: Status | D1: Send Date | E1: Notes | F1: Calendar Key | G1: Calendar Display | H1: Future Send Helper
A2: JIRA-1001 | B2: TEST | C2: In Progress | D2: 46388 | F2: =IF(AND($D2<>"",$B2<>""),TEXT($D2,"yyyymmdd")&"|"&COUNTIFS($D$2:$D2,$D2,$B$2:$B2,"<>"),"") -> 20270101|1 | G2: =IF($B2="","",$B2) -> TEST | H2: =IF(AND($D2>=TODAY(),$B2<>"",$C2<>"Completed",$C2<>"Cancelled"),$D2,999999999) -> 46388
A3: JIRA-1002 | B3: TEST | C3: In Progress | D3: 46420 | F3: =IF(AND($D3<>"",$B3<>""),TEXT($D3,"yyyymmdd")&"|"&COUNTIFS($D$2:$D3,$D3,$B$2:$B3,"<>"),"") -> 20270202|1 | G3: =IF($B3="","",$B3) -> TEST | H3: =IF(AND($D3>=TODAY(),$B3<>"",$C3<>"Completed",$C3<>"Cancelled"),$D3,999999999) -> 46420
A4: JIRA-1003 | B4: TEST | C4: Cancelled | D4: 46449 | F4: =IF(AND($D4<>"",$B4<>""),TEXT($D4,"yyyymmdd")&"|"&COUNTIFS($D$2:$D4,$D4,$B$2:$B4,"<>"),"") -> 20270303|1 | G4: =IF($B4="","",$B4) -> TEST | H4: =IF(AND($D4>=TODAY(),$B4<>"",$C4<>"Completed",$C4<>"Cancelled"),$D4,999999999) -> 999999999
A5: JIRA-1004 | B5: TEST | C5: Cancelled | D5: 46481 | F5: =IF(AND($D5<>"",$B5<>""),TEXT($D5,"yyyymmdd")&"|"&COUNTIFS($D$2:$D5,$D5,$B$2:$B5,"<>"),"") -> 20270404|1 | G5: =IF($B5="","",$B5) -> TEST | H5: =IF(AND($D5>=TODAY(),$B5<>"",$C5<>"Completed",$C5<>"Cancelled"),$D5,999999999) -> 999999999
A6: JIRA-1005 | B6: TEST | C6: Completed | D6: 46512 | F6: =IF(AND($D6<>"",$B6<>""),TEXT($D6,"yyyymmdd")&"|"&COUNTIFS($D$2:$D6,$D6,$B$2:$B6,"<>"),"") -> 20270505|1 | G6: =IF($B6="","",$B6) -> TEST | H6: =IF(AND($D6>=TODAY(),$B6<>"",$C6<>"Completed",$C6<>"Cancelled"),$D6,999999999) -> 999999999
A7: JIRA-1006 | B7: TEST | C7: Completed | D7: 46544 | F7: =IF(AND($D7<>"",$B7<>""),TEXT($D7,"yyyymmdd")&"|"&COUNTIFS($D$2:$D7,$D7,$B$2:$B7,"<>"),"") -> 20270606|1 | G7: =IF($B7="","",$B7) -> TEST | H7: =IF(AND($D7>=TODAY(),$B7<>"",$C7<>"Completed",$C7<>"Cancelled"),$D7,999999999) -> 999999999
A8: JIRA-1007 | B8: TEST | C8: In Progress | D8: 46210 | F8: =IF(AND($D8<>"",$B8<>""),TEXT($D8,"yyyymmdd")&"|"&COUNTIFS($D$2:$D8,$D8,$B$2:$B8,"<>"),"") -> 20260707|1 | G8: =IF($B8="","",$B8) -> TEST | H8: =IF(AND($D8>=TODAY(),$B8<>"",$C8<>"Completed",$C8<>"Cancelled"),$D8,999999999) -> 46210
A9: JIRA-1008 | B9: TEST | C9: Cancelled | D9: 46242 | F9: =IF(AND($D9<>"",$B9<>""),TEXT($D9,"yyyymmdd")&"|"&COUNTIFS($D$2:$D9,$D9,$B$2:$B9,"<>"),"") -> 20260808|1 | G9: =IF($B9="","",$B9) -> TEST | H9: =IF(AND($D9>=TODAY(),$B9<>"",$C9<>"Completed",$C9<>"Cancelled"),$D9,999999999) -> 999999999
A10: JIRA-1009 | B10: TEST | C10: Upcoming | D10: 46274 | F10: =IF(AND($D10<>"",$B10<>""),TEXT($D10,"yyyymmdd")&"|"&COUNTIFS($D$2:$D10,$D10,$B$2:$B10,"<>"),"") -> 20260909|1 | G10: =IF($B10="","",$B10) -> TEST | H10: =IF(AND($D10>=TODAY(),$B10<>"",$C10<>"Completed",$C10<>"Cancelled"),$D10,999999999) -> 46274
A11: JIRA-1010 | B11: TEST | C11: Upcoming | D11: 46305 | F11: =IF(AND($D11<>"",$B11<>""),TEXT($D11,"yyyymmdd")&"|"&COUNTIFS($D$2:$D11,$D11,$B$2:$B11,"<>"),"") -> 20261010|1 | G11: =IF($B11="","",$B11) -> TEST | H11: =IF(AND($D11>=TODAY(),$B11<>"",$C11<>"Completed",$C11<>"Cancelled"),$D11,999999999) -> 46305
A12: JIRA-1011 | B12: TEST | C12: Upcoming | D12: 46337 | F12: =IF(AND($D12<>"",$B12<>""),TEXT($D12,"yyyymmdd")&"|"&COUNTIFS($D$2:$D12,$D12,$B$2:$B12,"<>"),"") -> 20261111|1 | G12: =IF($B12="","",$B12) -> TEST | H12: =IF(AND($D12>=TODAY(),$B12<>"",$C12<>"Completed",$C12<>"Cancelled"),$D12,999999999) -> 46337
A13: JIRA-1012 | B13: TEST | C13: In Progress | D13: 46368 | F13: =IF(AND($D13<>"",$B13<>""),TEXT($D13,"yyyymmdd")&"|"&COUNTIFS($D$2:$D13,$D13,$B$2:$B13,"<>"),"") -> 20261212|1 | G13: =IF($B13="","",$B13) -> TEST | H13: =IF(AND($D13>=TODAY(),$B13<>"",$C13<>"Completed",$C13<>"Cancelled"),$D13,999999999) -> 46368
F14: =IF(AND($D14<>"",$B14<>""),TEXT($D14,"yyyymmdd")&"|"&COUNTIFS($D$2:$D14,$D14,$B$2:$B14,"<>"),"") | G14: =IF($B14="","",$B14) | H14: =IF(AND($D14>=TODAY(),$B14<>"",$C14<>"Completed",$C14<>"Cancelled"),$D14,999999999) -> 999999999
F15: =IF(AND($D15<>"",$B15<>""),TEXT($D15,"yyyymmdd")&"|"&COUNTIFS($D$2:$D15,$D15,$B$2:$B15,"<>"),"") | G15: =IF($B15="","",$B15) | H15: =IF(AND($D15>=TODAY(),$B15<>"",$C15<>"Completed",$C15<>"Cancelled"),$D15,999999999) -> 999999999
F16: =IF(AND($D16<>"",$B16<>""),TEXT($D16,"yyyymmdd")&"|"&COUNTIFS($D$2:$D16,$D16,$B$2:$B16,"<>"),"") | G16: =IF($B16="","",$B16) | H16: =IF(AND($D16>=TODAY(),$B16<>"",$C16<>"Completed",$C16<>"Cancelled"),$D16,999999999) -> 999999999
F17: =IF(AND($D17<>"",$B17<>""),TEXT($D17,"yyyymmdd")&"|"&COUNTIFS($D$2:$D17,$D17,$B$2:$B17,"<>"),"") | G17: =IF($B17="","",$B17) | H17: =IF(AND($D17>=TODAY(),$B17<>"",$C17<>"Completed",$C17<>"Cancelled"),$D17,999999999) -> 999999999
F18: =IF(AND($D18<>"",$B18<>""),TEXT($D18,"yyyymmdd")&"|"&COUNTIFS($D$2:$D18,$D18,$B$2:$B18,"<>"),"") | G18: =IF($B18="","",$B18) | H18: =IF(AND($D18>=TODAY(),$B18<>"",$C18<>"Completed",$C18<>"Cancelled"),$D18,999999999) -> 999999999
F19: =IF(AND($D19<>"",$B19<>""),TEXT($D19,"yyyymmdd")&"|"&COUNTIFS($D$2:$D19,$D19,$B$2:$B19,"<>"),"") | G19: =IF($B19="","",$B19) | H19: =IF(AND($D19>=TODAY(),$B19<>"",$C19<>"Completed",$C19<>"Cancelled"),$D19,999999999) -> 999999999
F20: =IF(AND($D20<>"",$B20<>""),TEXT($D20,"yyyymmdd")&"|"&COUNTIFS($D$2:$D20,$D20,$B$2:$B20,"<>"),"") | G20: =IF($B20="","",$B20) | H20: =IF(AND($D20>=TODAY(),$B20<>"",$C20<>"Completed",$C20<>"Cancelled"),$D20,999999999) -> 999999999
F21: =IF(AND($D21<>"",$B21<>""),TEXT($D21,"yyyymmdd")&"|"&COUNTIFS($D$2:$D21,$D21,$B$2:$B21,"<>"),"") | G21: =IF($B21="","",$B21) | H21: =IF(AND($D21>=TODAY(),$B21<>"",$C21<>"Completed",$C21<>"Cancelled"),$D21,999999999) -> 999999999
F22: =IF(AND($D22<>"",$B22<>""),TEXT($D22,"yyyymmdd")&"|"&COUNTIFS($D$2:$D22,$D22,$B$2:$B22,"<>"),"") | G22: =IF($B22="","",$B22) | H22: =IF(AND($D22>=TODAY(),$B22<>"",$C22<>"Completed",$C22<>"Cancelled"),$D22,999999999) -> 999999999
F23: =IF(AND($D23<>"",$B23<>""),TEXT($D23,"yyyymmdd")&"|"&COUNTIFS($D$2:$D23,$D23,$B$2:$B23,"<>"),"") | G23: =IF($B23="","",$B23) | H23: =IF(AND($D23>=TODAY(),$B23<>"",$C23<>"Completed",$C23<>"Cancelled"),$D23,999999999) -> 999999999
F24: =IF(AND($D24<>"",$B24<>""),TEXT($D24,"yyyymmdd")&"|"&COUNTIFS($D$2:$D24,$D24,$B$2:$B24,"<>"),"") | G24: =IF($B24="","",$B24) | H24: =IF(AND($D24>=TODAY(),$B24<>"",$C24<>"Completed",$C24<>"Cancelled"),$D24,999999999) -> 999999999
F25: =IF(AND($D25<>"",$B25<>""),TEXT($D25,"yyyymmdd")&"|"&COUNTIFS($D$2:$D25,$D25,$B$2:$B25,"<>"),"") | G25: =IF($B25="","",$B25) | H25: =IF(AND($D25>=TODAY(),$B25<>"",$C25<>"Completed",$C25<>"Cancelled"),$D25,999999999) -> 999999999
... F201: =IF(AND($D201<>"",$B201<>""),TEXT($D201,"yyyymmdd")&"|"&COUNTIFS($D$2:$D201,$D201,$B$2:$B201,"<>"),"") | G201: =IF($B201="","",$B201) | H201: =IF(AND($D201>=TODAY(),$B201<>"",$C201<>"Completed",$C201<>"Cancelled"),$D201,999999999) -> 999999999

Sheet January 2027 Calendar
A1: January 2027 Project Calendar
A3: Week | B3: Mon | C3: Tue | D3: Wed | E3: Thu | F3: Fri | G3: Sat | H3: Sun
A4: Week 1 | F4: 46388 | G4: 46389 | H4: 46390
B5: =IF(B4="","",IFERROR(VLOOKUP(TEXT(B4,"yyyymmdd")&"|1",'Project Tracker'!$F$2:$G$201,2,FALSE),"")&IFERROR(CHAR(10)&VLOOKUP(TEXT(B4,"yyyymmdd")&"|2",'Project Tracker'!$F$2:$G$201,2,FALSE),"")&IFERROR(CHAR(10)&VLOOKUP(TEXT(B4,"yyyymmdd")&"|3",'Project Tracker'!$F$2:$G$201,2,FALSE),"")&IF(COUNTIFS('Project Tracker'!$D$2:$D$201,B4,'Project Tracker'!$B$2:$B$201,"<>")>3,CHAR(10)&"+ "&(COUNTIFS('Project Tracker'!$D$2:$D$201,B4,'Project Tracker'!$B$2:$B$201,"<>")-3)&" more","")) | C5: =IF(C4="","",IFERROR(VLOOKUP(TEXT(C4,"yyyymmdd")&"|1",'Project Tracker'!$F$2:$G$201,2,FALSE),"")&IFERROR(CHAR(10)&VLOOKUP(TEXT(C4,"yyyymmdd")&"|2",'Project Tracker'!$F$2:$G$201,2,FALSE),"")&IFERROR(CHAR(10)&VLOOKUP(TEXT(C4,"yyyymmdd")&"|3",'Project Tracker'!$F$2:$G$201,2,FALSE),"")&IF(COUNTIFS('Project Tracker'!$D$2:$D$201,C4,'Project Tracker'!$B$2:$B$201,"<>")>3,CHAR(10)&"+ "&(COUNTIFS('Project Tracker'!$D$2:$D$201,C4,'Project Tracker'!$B$2:$B$201,"<>")-3)&" more","")) | D5: =IF(D4="","",IFERROR(VLOOKUP(TEXT(D4,"yyyymmdd")&"|1",'Project Tracker'!$F$2:$G$201,2,FALSE),"")&IFERROR(CHAR(10)&VLOOKUP(TEXT(D4,"yyyymmdd")&"|2",'Project Tracker'!$F$2:$G$201,2,FALSE),"")&IFERROR(CHAR(10)&VLOOKUP(TEXT(D4,"yyyymmdd")&"|3",'Project Tracker'!$F$2:$G$201,2,FALSE),"")&IF(COUNTIFS('Project Tracker'!$D$2:$D$201,D4,'Project Tracker'!$B$2:$B$201,"<>")>3,CHAR(10)&"+ "&(COUNTIFS('Project Tracker'!$D$2:$D$201,D4,'Project Tracker'!$B$2:$B$201,"<>")-3)&" more","")) | E5: =IF(E4="","",IFERROR(VLOOKUP(TEXT(E4,"yyyymmdd")&"|1",'Project Tracker'!$F$2:$G$201,2,FALSE),"")&IFERROR(CHAR(10)&VLOOKUP(TEXT(E4,"yyyymmdd")&"|2",'Project Tracker'!$F$2:$G$201,2,FALSE),"")&IFERROR(CHAR(10)&VLOOKUP(TEXT(E4,"yyyymmdd")&"|3",'Project Tracker'!$F$2:$G$201,2,FALSE),"")&IF(COUNTIFS('Project Tracker'!$D$2:$D$201,E4,'Project Tracker'!$B$2:$B$201,"<>")>3,CHAR(10)&"+ "&(COUNTIFS('Project Tracker'!$D$2:$D$201,E4,'Project Tracker'!$B$2:$B$201,"<>")-3)&" more","")) | F5: =IF(F4="","",IFERROR(VLOOKUP(TEXT(F4,"yyyymmdd")&"|1",'Project Tracker'!$F$2:$G$201,2,FALSE),"")&IFERROR(CHAR(10)&VLOOKUP(TEXT(F4,"yyyymmdd")&"|2",'Project Tracker'!$F$2:$G$201,2,FALSE),"")&IFERROR(CHAR(10)&VLOOKUP(TEXT(F4,"yyyymmdd")&"|3",'Project Tracker'!$F$2:$G$201,2,FALSE),"")&IF(COUNTIFS('Project Tracker'!$D$2:$D$201,F4,'Project Tracker'!$B$2:$B$201,"<>")>3,CHAR(10)&"+ "&(COUNTIFS('Project Tracker'!$D$2:$D$201,F4,'Project Tracker'!$B$2:$B$201,"<>")-3)&" more","")) -> TEST | G5: =IF(G4="","",IFERROR(VLOOKUP(TEXT(G4,"yyyymmdd")&"|1",'Project Tracker'!$F$2:$G$201,2,FALSE),"")&IFERROR(CHAR(10)&VLOOKUP(TEXT(G4,"yyyymmdd")&"|2",'Project Tracker'!$F$2:$G$201,2,FALSE),"")&IFERROR(CHAR(10)&VLOOKUP(TEXT(G4,"yyyymmdd")&"|3",'Project Tracker'!$F$2:$G$201,2,FALSE),"")&IF(COUNTIFS('Project Tracker'!$D$2:$D$201,G4,'Project Tracker'!$B$2:$B$201,"<>")>3,CHAR(10)&"+ "&(COUNTIFS('Project Tracker'!$D$2:$D$201,G4,'Project Tracker'!$B$2:$B$201,"<>")-3)&" more","")) | H5: =IF(H4="","",IFERROR(VLOOKUP(TEXT(H4,"yyyymmdd")&"|1",'Project Tracker'!$F$2:$G$201,2,FALSE),"")&IFERROR(CHAR(10)&VLOOKUP(TEXT(H4,"yyyymmdd")&"|2",'Project Tracker'!$F$2:$G$201,2,FALSE),"")&IFERROR(CHAR(10)&VLOOKUP(TEXT(H4,"yyyymmdd")&"|3",'Project Tracker'!$F$2:$G$201,2,FALSE),"")&IF(COUNTIFS('Project Tracker'!$D$2:$D$201,H4,'Project Tracker'!$B$2:$B$201,"<>")>3,CHAR(10)&"+ "&(COUNTIFS('Project Tracker'!$D$2:$D$201,H4,'Project Tracker'!$B$2:$B$201,"<>")-3)&" more",""))
A6: Week 2 | B6: 46391 | C6: 46392 | D6: 46393 | E6: 46394 | F6: 46395 | G6: 46396 | H6: 46397
B7: =IF(B6="","",IFERROR(VLOOKUP(TEXT(B6,"yyyymmdd")&"|1",'Project Tracker'!$F$2:$G$201,2,FALSE),"")&IFERROR(CHAR(10)&VLOOKUP(TEXT(B6,"yyyymmdd")&"|2",'Project Tracker'!$F$2:$G$201,2,FALSE),"")&IFERROR(CHAR(10)&VLOOKUP(TEXT(B6,"yyyymmdd")&"|3",'Project Tracker'!$F$2:$G$201,2,FALSE),"")&IF(COUNTIFS('Project Tracker'!$D$2:$D$201,B6,'Project Tracker'!$B$2:$B$201,"<>")>3,CHAR(10)&"+ "&(COUNTIFS('Project Tracker'!$D$2:$D$201,B6,'Project Tracker'!$B$2:$B$201,"<>")-3)&" more","")) | C7: =IF(C6="","",IFERROR(VLOOKUP(TEXT(C6,"yyyymmdd")&"|1",'Project Tracker'!$F$2:$G$201,2,FALSE),"")&IFERROR(CHAR(10)&VLOOKUP(TEXT(C6,"yyyymmdd")&"|2",'Project Tracker'!$F$2:$G$201,2,FALSE),"")&IFERROR(CHAR(10)&VLOOKUP(TEXT(C6,"yyyymmdd")&"|3",'Project Tracker'!$F$2:$G$201,2,FALSE),"")&IF(COUNTIFS('Project Tracker'!$D$2:$D$201,C6,'Project Tracker'!$B$2:$B$201,"<>")>3,CHAR(10)&"+ "&(COUNTIFS('Project Tracker'!$D$2:$D$201,C6,'Project Tracker'!$B$2:$B$201,"<>")-3)&" more","")) | D7: =IF(D6="","",IFERROR(VLOOKUP(TEXT(D6,"yyyymmdd")&"|1",'Project Tracker'!$F$2:$G$201,2,FALSE),"")&IFERROR(CHAR(10)&VLOOKUP(TEXT(D6,"yyyymmdd")&"|2",'Project Tracker'!$F$2:$G$201,2,FALSE),"")&IFERROR(CHAR(10)&VLOOKUP(TEXT(D6,"yyyymmdd")&"|3",'Project Tracker'!$F$2:$G$201,2,FALSE),"")&IF(COUNTIFS('Project Tracker'!$D$2:$D$201,D6,'Project Tracker'!$B$2:$B$201,"<>")>3,CHAR(10)&"+ "&(COUNTIFS('Project Tracker'!$D$2:$D$201,D6,'Project Tracker'!$B$2:$B$201,"<>")-3)&" more","")) | E7: =IF(E6="","",IFERROR(VLOOKUP(TEXT(E6,"yyyymmdd")&"|1",'Project Tracker'!$F$2:$G$201,2,FALSE),"")&IFERROR(CHAR(10)&VLOOKUP(TEXT(E6,"yyyymmdd")&"|2",'Project Tracker'!$F$2:$G$201,2,FALSE),"")&IFERROR(CHAR(10)&VLOOKUP(TEXT(E6,"yyyymmdd")&"|3",'Project Tracker'!$F$2:$G$201,2,FALSE),"")&IF(COUNTIFS('Project Tracker'!$D$2:$D$201,E6,'Project Tracker'!$B$2:$B$201,"<>")>3,CHAR(10)&"+ "&(COUNTIFS('Project Tracker'!$D$2:$D$201,E6,'Project Tracker'!$B$2:$B$201,"<>")-3)&" more","")) | F7: =IF(F6="","",IFERROR(VLOOKUP(TEXT(F6,"yyyymmdd")&"|1",'Project Tracker'!$F$2:$G$201,2,FALSE),"")&IFERROR(CHAR(10)&VLOOKUP(TEXT(F6,"yyyymmdd")&"|2",'Project Tracker'!$F$2:$G$201,2,FALSE),"")&IFERROR(CHAR(10)&VLOOKUP(TEXT(F6,"yyyymmdd")&"|3",'Project Tracker'!$F$2:$G$201,2,FALSE),"")&IF(COUNTIFS('Project Tracker'!$D$2:$D$201,F6,'Project Tracker'!$B$2:$B$201,"<>")>3,CHAR(10)&"+ "&(COUNTIFS('Project Tracker'!$D$2:$D$201,F6,'Project Tracker'!$B$2:$B$201,"<>")-3)&" more","")) | G7: =IF(G6="","",IFERROR(VLOOKUP(TEXT(G6,"yyyymmdd")&"|1",'Project Tracker'!$F$2:$G$201,2,FALSE),"")&IFERROR(CHAR(10)&VLOOKUP(TEXT(G6,"yyyymmdd")&"|2",'Project Tracker'!$F$2:$G$201,2,FALSE),"")&IFERROR(CHAR(10)&VLOOKUP(TEXT(G6,"yyyymmdd")&"|3",'Project Tracker'!$F$2:$G$201,2,FALSE),"")&IF(COUNTIFS('Project Tracker'!$D$2:$D$201,G6,'Project Tracker'!$B$2:$B$201,"<>")>3,CHAR(10)&"+ "&(COUNTIFS('Project Tracker'!$D$2:$D$201,G6,'Project Tracker'!$B$2:$B$201,"<>")-3)&" more","")) | H7: =IF(H6="","",IFERROR(VLOOKUP(TEXT(H6,"yyyymmdd")&"|1",'Project Tracker'!$F$2:$G$201,2,FALSE),"")&IFERROR(CHAR(10)&VLOOKUP(TEXT(H6,"yyyymmdd")&"|2",'Project Tracker'!$F$2:$G$201,2,FALSE),"")&IFERROR(CHAR(10)&VLOOKUP(TEXT(H6,"yyyymmdd")&"|3",'Project Tracker'!$F$2:$G$201,2,FALSE),"")&IF(COUNTIFS('Project Tracker'!$D$2:$D$201,H6,'Project Tracker'!$B$2:$B$201,"<>")>3,CHAR(10)&"+ "&(COUNTIFS('Project Tracker'!$D$2:$D$201,H6,'Project Tracker'!$B$2:$B$201,"<>")-3)&" more",""))
A8: Week 3 | B8: 46398 | C8: 46399 | D8: 46400 | E8: 46401 | F8: 46402 | G8: 46403 | H8: 46404
B9: =IF(B8="","",IFERROR(VLOOKUP(TEXT(B8,"yyyymmdd")&"|1",'Project Tracker'!$F$2:$G$201,2,FALSE),"")&IFERROR(CHAR(10)&VLOOKUP(TEXT(B8,"yyyymmdd")&"|2",'Project Tracker'!$F$2:$G$201,2,FALSE),"")&IFERROR(CHAR(10)&VLOOKUP(TEXT(B8,"yyyymmdd")&"|3",'Project Tracker'!$F$2:$G$201,2,FALSE),"")&IF(COUNTIFS('Project Tracker'!$D$2:$D$201,B8,'Project Tracker'!$B$2:$B$201,"<>")>3,CHAR(10)&"+ "&(COUNTIFS('Project Tracker'!$D$2:$D$201,B8,'Project Tracker'!$B$2:$B$201,"<>")-3)&" more","")) | C9: =IF(C8="","",IFERROR(VLOOKUP(TEXT(C8,"yyyymmdd")&"|1",'Project Tracker'!$F$2:$G$201,2,FALSE),"")&IFERROR(CHAR(10)&VLOOKUP(TEXT(C8,"yyyymmdd")&"|2",'Project Tracker'!$F$2:$G$201,2,FALSE),"")&IFERROR(CHAR(10)&VLOOKUP(TEXT(C8,"yyyymmdd")&"|3",'Project Tracker'!$F$2:$G$201,2,FALSE),"")&IF(COUNTIFS('Project Tracker'!$D$2:$D$201,C8,'Project Tracker'!$B$2:$B$201,"<>")>3,CHAR(10)&"+ "&(COUNTIFS('Project Tracker'!$D$2:$D$201,C8,'Project Tracker'!$B$2:$B$201,"<>")-3)&" more","")) | D9: =IF(D8="","",IFERROR(VLOOKUP(TEXT(D8,"yyyymmdd")&"|1",'Project Tracker'!$F$2:$G$201,2,FALSE),"")&IFERROR(CHAR(10)&VLOOKUP(TEXT(D8,"yyyymmdd")&"|2",'Project Tracker'!$F$2:$G$201,2,FALSE),"")&IFERROR(CHAR(10)&VLOOKUP(TEXT(D8,"yyyymmdd")&"|3",'Project Tracker'!$F$2:$G$201,2,FALSE),"")&IF(COUNTIFS('Project Tracker'!$D$2:$D$201,D8,'Project Tracker'!$B$2:$B$201,"<>")>3,CHAR(10)&"+ "&(COUNTIFS('Project Tracker'!$D$2:$D$201,D8,'Project Tracker'!$B$2:$B$201,"<>")-3)&" more","")) | E9: =IF(E8="","",IFERROR(VLOOKUP(TEXT(E8,"yyyymmdd")&"|1",'Project Tracker'!$F$2:$G$201,2,FALSE),"")&IFERROR(CHAR(10)&VLOOKUP(TEXT(E8,"yyyymmdd")&"|2",'Project Tracker'!$F$2:$G$201,2,FALSE),"")&IFERROR(CHAR(10)&VLOOKUP(TEXT(E8,"yyyymmdd")&"|3",'Project Tracker'!$F$2:$G$201,2,FALSE),"")&IF(COUNTIFS('Project Tracker'!$D$2:$D$201,E8,'Project Tracker'!$B$2:$B$201,"<>")>3,CHAR(10)&"+ "&(COUNTIFS('Project Tracker'!$D$2:$D$201,E8,'Project Tracker'!$B$2:$B$201,"<>")-3)&" more","")) | F9: =IF(F8="","",IFERROR(VLOOKUP(TEXT(F8,"yyyymmdd")&"|1",'Project Tracker'!$F$2:$G$201,2,FALSE),"")&IFERROR(CHAR(10)&VLOOKUP(TEXT(F8,"yyyymmdd")&"|2",'Project Tracker'!$F$2:$G$201,2,FALSE),"")&IFERROR(CHAR(10)&VLOOKUP(TEXT(F8,"yyyymmdd")&"|3",'Project Tracker'!$F$2:$G$201,2,FALSE),"")&IF(COUNTIFS('Project Tracker'!$D$2:$D$201,F8,'Project Tracker'!$B$2:$B$201,"<>")>3,CHAR(10)&"+ "&(COUNTIFS('Project Tracker'!$D$2:$D$201,F8,'Project Tracker'!$B$2:$B$201,"<>")-3)&" more","")) | G9: =IF(G8="","",IFERROR(VLOOKUP(TEXT(G8,"yyyymmdd")&"|1",'Project Tracker'!$F$2:$G$201,2,FALSE),"")&IFERROR(CHAR(10)&VLOOKUP(TEXT(G8,"yyyymmdd")&"|2",'Project Tracker'!$F$2:$G$201,2,FALSE),"")&IFERROR(CHAR(10)&VLOOKUP(TEXT(G8,"yyyymmdd")&"|3",'Project Tracker'!$F$2:$G$201,2,FALSE),"")&IF(COUNTIFS('Project Tracker'!$D$2:$D$201,G8,'Project Tracker'!$B$2:$B$201,"<>")>3,CHAR(10)&"+ "&(COUNTIFS('Project Tracker'!$D$2:$D$201,G8,'Project Tracker'!$B$2:$B$201,"<>")-3)&" more","")) | H9: =IF(H8="","",IFERROR(VLOOKUP(TEXT(H8,"yyyymmdd")&"|1",'Project Tracker'!$F$2:$G$201,2,FALSE),"")&IFERROR(CHAR(10)&VLOOKUP(TEXT(H8,"yyyymmdd")&"|2",'Project Tracker'!$F$2:$G$201,2,FALSE),"")&IFERROR(CHAR(10)&VLOOKUP(TEXT(H8,"yyyymmdd")&"|3",'Project Tracker'!$F$2:$G$201,2,FALSE),"")&IF(COUNTIFS('Project Tracker'!$D$2:$D$201,H8,'Project Tracker'!$B$2:$B$201,"<>")>3,CHAR(10)&"+ "&(COUNTIFS('Project Tracker'!$D$2:$D$201,H8,'Project Tracker'!$B$2:$B$201,"<>")-3)&" more",""))
A10: Week 4 | B10: 46405 | C10: 46406 | D10: 46407 | E10: 46408 | F10: 46409 | G10: 46410 | H10: 46411
B11: =IF(B10="","",IFERROR(VLOOKUP(TEXT(B10,"yyyymmdd")&"|1",'Project Tracker'!$F$2:$G$201,2,FALSE),"")&IFERROR(CHAR(10)&VLOOKUP(TEXT(B10,"yyyymmdd")&"|2",'Project Tracker'!$F$2:$G$201,2,FALSE),"")&IFERROR(CHAR(10)&VLOOKUP(TEXT(B10,"yyyymmdd")&"|3",'Project Tracker'!$F$2:$G$201,2,FALSE),"")&IF(COUNTIFS('Project Tracker'!$D$2:$D$201,B10,'Project Tracker'!$B$2:$B$201,"<>")>3,CHAR(10)&"+ "&(COUNTIFS('Project Tracker'!$D$2:$D$201,B10,'Project Tracker'!$B$2:$B$201,"<>")-3)&" more","")) | C11: =IF(C10="","",IFERROR(VLOOKUP(TEXT(C10,"yyyymmdd")&"|1",'Project Tracker'!$F$2:$G$201,2,FALSE),"")&IFERROR(CHAR(10)&VLOOKUP(TEXT(C10,"yyyymmdd")&"|2",'Project Tracker'!$F$2:$G$201,2,FALSE),"")&IFERROR(CHAR(10)&VLOOKUP(TEXT(C10,"yyyymmdd")&"|3",'Project Tracker'!$F$2:$G$201,2,FALSE),"")&IF(COUNTIFS('Project Tracker'!$D$2:$D$201,C10,'Project Tracker'!$B$2:$B$201,"<>")>3,CHAR(10)&"+ "&(COUNTIFS('Project Tracker'!$D$2:$D$201,C10,'Project Tracker'!$B$2:$B$201,"<>")-3)&" more","")) | D11: =IF(D10="","",IFERROR(VLOOKUP(TEXT(D10,"yyyymmdd")&"|1",'Project Tracker'!$F$2:$G$201,2,FALSE),"")&IFERROR(CHAR(10)&VLOOKUP(TEXT(D10,"yyyymmdd")&"|2",'Project Tracker'!$F$2:$G$201,2,FALSE),"")&IFERROR(CHAR(10)&VLOOKUP(TEXT(D10,"yyyymmdd")&"|3",'Project Tracker'!$F$2:$G$201,2,FALSE),"")&IF(COUNTIFS('Project Tracker'!$D$2:$D$201,D10,'Project Tracker'!$B$2:$B$201,"<>")>3,CHAR(10)&"+ "&(COUNTIFS('Project Tracker'!$D$2:$D$201,D10,'Project Tracker'!$B$2:$B$201,"<>")-3)&" more","")) | E11: =IF(E10="","",IFERROR(VLOOKUP(TEXT(E10,"yyyymmdd")&"|1",'Project Tracker'!$F$2:$G$201,2,FALSE),"")&IFERROR(CHAR(10)&VLOOKUP(TEXT(E10,"yyyymmdd")&"|2",'Project Tracker'!$F$2:$G$201,2,FALSE),"")&IFERROR(CHAR(10)&VLOOKUP(TEXT(E10,"yyyymmdd")&"|3",'Project Tracker'!$F$2:$G$201,2,FALSE),"")&IF(COUNTIFS('Project Tracker'!$D$2:$D$201,E10,'Project Tracker'!$B$2:$B$201,"<>")>3,CHAR(10)&"+ "&(COUNTIFS('Project Tracker'!$D$2:$D$201,E10,'Project Tracker'!$B$2:$B$201,"<>")-3)&" more","")) | F11: =IF(F10="","",IFERROR(VLOOKUP(TEXT(F10,"yyyymmdd")&"|1",'Project Tracker'!$F$2:$G$201,2,FALSE),"")&IFERROR(CHAR(10)&VLOOKUP(TEXT(F10,"yyyymmdd")&"|2",'Project Tracker'!$F$2:$G$201,2,FALSE),"")&IFERROR(CHAR(10)&VLOOKUP(TEXT(F10,"yyyymmdd")&"|3",'Project Tracker'!$F$2:$G$201,2,FALSE),"")&IF(COUNTIFS('Project Tracker'!$D$2:$D$201,F10,'Project Tracker'!$B$2:$B$201,"<>")>3,CHAR(10)&"+ "&(COUNTIFS('Project Tracker'!$D$2:$D$201,F10,'Project Tracker'!$B$2:$B$201,"<>")-3)&" more","")) | G11: =IF(G10="","",IFERROR(VLOOKUP(TEXT(G10,"yyyymmdd")&"|1",'Project Tracker'!$F$2:$G$201,2,FALSE),"")&IFERROR(CHAR(10)&VLOOKUP(TEXT(G10,"yyyymmdd")&"|2",'Project Tracker'!$F$2:$G$201,2,FALSE),"")&IFERROR(CHAR(10)&VLOOKUP(TEXT(G10,"yyyymmdd")&"|3",'Project Tracker'!$F$2:$G$201,2,FALSE),"")&IF(COUNTIFS('Project Tracker'!$D$2:$D$201,G10,'Project Tracker'!$B$2:$B$201,"<>")>3,CHAR(10)&"+ "&(COUNTIFS('Project Tracker'!$D$2:$D$201,G10,'Project Tracker'!$B$2:$B$201,"<>")-3)&" more","")) | H11: =IF(H10="","",IFERROR(VLOOKUP(TEXT(H10,"yyyymmdd")&"|1",'Project Tracker'!$F$2:$G$201,2,FALSE),"")&IFERROR(CHAR(10)&VLOOKUP(TEXT(H10,"yyyymmdd")&"|2",'Project Tracker'!$F$2:$G$201,2,FALSE),"")&IFERROR(CHAR(10)&VLOOKUP(TEXT(H10,"yyyymmdd")&"|3",'Project Tracker'!$F$2:$G$201,2,FALSE),"")&IF(COUNTIFS('Project Tracker'!$D$2:$D$201,H10,'Project Tracker'!$B$2:$B$201,"<>")>3,CHAR(10)&"+ "&(COUNTIFS('Project Tracker'!$D$2:$D$201,H10,'Project Tracker'!$B$2:$B$201,"<>")-3)&" more",""))
A12: Week 5 | B12: 46412 | C12: 46413 | D12: 46414 | E12: 46415 | F12: 46416 | G12: 46417 | H12: 46418
B13: =IF(B12="","",IFERROR(VLOOKUP(TEXT(B12,"yyyymmdd")&"|1",'Project Tracker'!$F$2:$G$201,2,FALSE),"")&IFERROR(CHAR(10)&VLOOKUP(TEXT(B12,"yyyymmdd")&"|2",'Project Tracker'!$F$2:$G$201,2,FALSE),"")&IFERROR(CHAR(10)&VLOOKUP(TEXT(B12,"yyyymmdd")&"|3",'Project Tracker'!$F$2:$G$201,2,FALSE),"")&IF(COUNTIFS('Project Tracker'!$D$2:$D$201,B12,'Project Tracker'!$B$2:$B$201,"<>")>3,CHAR(10)&"+ "&(COUNTIFS('Project Tracker'!$D$2:$D$201,B12,'Project Tracker'!$B$2:$B$201,"<>")-3)&" more","")) | C13: =IF(C12="","",IFERROR(VLOOKUP(TEXT(C12,"yyyymmdd")&"|1",'Project Tracker'!$F$2:$G$201,2,FALSE),"")&IFERROR(CHAR(10)&VLOOKUP(TEXT(C12,"yyyymmdd")&"|2",'Project Tracker'!$F$2:$G$201,2,FALSE),"")&IFERROR(CHAR(10)&VLOOKUP(TEXT(C12,"yyyymmdd")&"|3",'Project Tracker'!$F$2:$G$201,2,FALSE),"")&IF(COUNTIFS('Project Tracker'!$D$2:$D$201,C12,'Project Tracker'!$B$2:$B$201,"<>")>3,CHAR(10)&"+ "&(COUNTIFS('Project Tracker'!$D$2:$D$201,C12,'Project Tracker'!$B$2:$B$201,"<>")-3)&" more","")) | D13: =IF(D12="","",IFERROR(VLOOKUP(TEXT(D12,"yyyymmdd")&"|1",'Project Tracker'!$F$2:$G$201,2,FALSE),"")&IFERROR(CHAR(10)&VLOOKUP(TEXT(D12,"yyyymmdd")&"|2",'Project Tracker'!$F$2:$G$201,2,FALSE),"")&IFERROR(CHAR(10)&VLOOKUP(TEXT(D12,"yyyymmdd")&"|3",'Project Tracker'!$F$2:$G$201,2,FALSE),"")&IF(COUNTIFS('Project Tracker'!$D$2:$D$201,D12,'Project Tracker'!$B$2:$B$201,"<>")>3,CHAR(10)&"+ "&(COUNTIFS('Project Tracker'!$D$2:$D$201,D12,'Project Tracker'!$B$2:$B$201,"<>")-3)&" more","")) | E13: =IF(E12="","",IFERROR(VLOOKUP(TEXT(E12,"yyyymmdd")&"|1",'Project Tracker'!$F$2:$G$201,2,FALSE),"")&IFERROR(CHAR(10)&VLOOKUP(TEXT(E12,"yyyymmdd")&"|2",'Project Tracker'!$F$2:$G$201,2,FALSE),"")&IFERROR(CHAR(10)&VLOOKUP(TEXT(E12,"yyyymmdd")&"|3",'Project Tracker'!$F$2:$G$201,2,FALSE),"")&IF(COUNTIFS('Project Tracker'!$D$2:$D$201,E12,'Project Tracker'!$B$2:$B$201,"<>")>3,CHAR(10)&"+ "&(COUNTIFS('Project Tracker'!$D$2:$D$201,E12,'Project Tracker'!$B$2:$B$201,"<>")-3)&" more","")) | F13: =IF(F12="","",IFERROR(VLOOKUP(TEXT(F12,"yyyymmdd")&"|1",'Project Tracker'!$F$2:$G$201,2,FALSE),"")&IFERROR(CHAR(10)&VLOOKUP(TEXT(F12,"yyyymmdd")&"|2",'Project Tracker'!$F$2:$G$201,2,FALSE),"")&IFERROR(CHAR(10)&VLOOKUP(TEXT(F12,"yyyymmdd")&"|3",'Project Tracker'!$F$2:$G$201,2,FALSE),"")&IF(COUNTIFS('Project Tracker'!$D$2:$D$201,F12,'Project Tracker'!$B$2:$B$201,"<>")>3,CHAR(10)&"+ "&(COUNTIFS('Project Tracker'!$D$2:$D$201,F12,'Project Tracker'!$B$2:$B$201,"<>")-3)&" more","")) | G13: =IF(G12="","",IFERROR(VLOOKUP(TEXT(G12,"yyyymmdd")&"|1",'Project Tracker'!$F$2:$G$201,2,FALSE),"")&IFERROR(CHAR(10)&VLOOKUP(TEXT(G12,"yyyymmdd")&"|2",'Project Tracker'!$F$2:$G$201,2,FALSE),"")&IFERROR(CHAR(10)&VLOOKUP(TEXT(G12,"yyyymmdd")&"|3",'Project Tracker'!$F$2:$G$201,2,FALSE),"")&IF(COUNTIFS('Project Tracker'!$D$2:$D$201,G12,'Project Tracker'!$B$2:$B$201,"<>")>3,CHAR(10)&"+ "&(COUNTIFS('Project Tracker'!$D$2:$D$201,G12,'Project Tracker'!$B$2:$B$201,"<>")-3)&" more","")) | H13: =IF(H12="","",IFERROR(VLOOKUP(TEXT(H12,"yyyymmdd")&"|1",'Project Tracker'!$F$2:$G$201,2,FALSE),"")&IFERROR(CHAR(10)&VLOOKUP(TEXT(H12,"yyyymmdd")&"|2",'Project Tracker'!$F$2:$G$201,2,FALSE),"")&IFERROR(CHAR(10)&VLOOKUP(TEXT(H12,"yyyymmdd")&"|3",'Project Tracker'!$F$2:$G$201,2,FALSE),"")&IF(COUNTIFS('Project Tracker'!$D$2:$D$201,H12,'Project Tracker'!$B$2:$B$201,"<>")>3,CHAR(10)&"+ "&(COUNTIFS('Project Tracker'!$D$2:$D$201,H12,'Project Tracker'!$B$2:$B$201,"<>")-3)&" more",""))
B15: =IF(B14="","",IFERROR(VLOOKUP(TEXT(B14,"yyyymmdd")&"|1",'Project Tracker'!$F$2:$G$201,2,FALSE),"")&IFERROR(CHAR(10)&VLOOKUP(TEXT(B14,"yyyymmdd")&"|2",'Project Tracker'!$F$2:$G$201,2,FALSE),"")&IFERROR(CHAR(10)&VLOOKUP(TEXT(B14,"yyyymmdd")&"|3",'Project Tracker'!$F$2:$G$201,2,FALSE),"")&IF(COUNTIFS('Project Tracker'!$D$2:$D$201,B14,'Project Tracker'!$B$2:$B$201,"<>")>3,CHAR(10)&"+ "&(COUNTIFS('Project Tracker'!$D$2:$D$201,B14,'Project Tracker'!$B$2:$B$201,"<>")-3)&" more","")) | C15: =IF(C14="","",IFERROR(VLOOKUP(TEXT(C14,"yyyymmdd")&"|1",'Project Tracker'!$F$2:$G$201,2,FALSE),"")&IFERROR(CHAR(10)&VLOOKUP(TEXT(C14,"yyyymmdd")&"|2",'Project Tracker'!$F$2:$G$201,2,FALSE),"")&IFERROR(CHAR(10)&VLOOKUP(TEXT(C14,"yyyymmdd")&"|3",'Project Tracker'!$F$2:$G$201,2,FALSE),"")&IF(COUNTIFS('Project Tracker'!$D$2:$D$201,C14,'Project Tracker'!$B$2:$B$201,"<>")>3,CHAR(10)&"+ "&(COUNTIFS('Project Tracker'!$D$2:$D$201,C14,'Project Tracker'!$B$2:$B$201,"<>")-3)&" more","")) | D15: =IF(D14="","",IFERROR(VLOOKUP(TEXT(D14,"yyyymmdd")&"|1",'Project Tracker'!$F$2:$G$201,2,FALSE),"")&IFERROR(CHAR(10)&VLOOKUP(TEXT(D14,"yyyymmdd")&"|2",'Project Tracker'!$F$2:$G$201,2,FALSE),"")&IFERROR(CHAR(10)&VLOOKUP(TEXT(D14,"yyyymmdd")&"|3",'Project Tracker'!$F$2:$G$201,2,FALSE),"")&IF(COUNTIFS('Project Tracker'!$D$2:$D$201,D14,'Project Tracker'!$B$2:$B$201,"<>")>3,CHAR(10)&"+ "&(COUNTIFS('Project Tracker'!$D$2:$D$201,D14,'Project Tracker'!$B$2:$B$201,"<>")-3)&" more","")) | E15: =IF(E14="","",IFERROR(VLOOKUP(TEXT(E14,"yyyymmdd")&"|1",'Project Tracker'!$F$2:$G$201,2,FALSE),"")&IFERROR(CHAR(10)&VLOOKUP(TEXT(E14,"yyyymmdd")&"|2",'Project Tracker'!$F$2:$G$201,2,FALSE),"")&IFERROR(CHAR(10)&VLOOKUP(TEXT(E14,"yyyymmdd")&"|3",'Project Tracker'!$F$2:$G$201,2,FALSE),"")&IF(COUNTIFS('Project Tracker'!$D$2:$D$201,E14,'Project Tracker'!$B$2:$B$201,"<>")>3,CHAR(10)&"+ "&(COUNTIFS('Project Tracker'!$D$2:$D$201,E14,'Project Tracker'!$B$2:$B$201,"<>")-3)&" more","")) | F15: =IF(F14="","",IFERROR(VLOOKUP(TEXT(F14,"yyyymmdd")&"|1",'Project Tracker'!$F$2:$G$201,2,FALSE),"")&IFERROR(CHAR(10)&VLOOKUP(TEXT(F14,"yyyymmdd")&"|2",'Project Tracker'!$F$2:$G$201,2,FALSE),"")&IFERROR(CHAR(10)&VLOOKUP(TEXT(F14,"yyyymmdd")&"|3",'Project Tracker'!$F$2:$G$201,2,FALSE),"")&IF(COUNTIFS('Project Tracker'!$D$2:$D$201,F14,'Project Tracker'!$B$2:$B$201,"<>")>3,CHAR(10)&"+ "&(COUNTIFS('Project Tracker'!$D$2:$D$201,F14,'Project Tracker'!$B$2:$B$201,"<>")-3)&" more","")) | G15: =IF(G14="","",IFERROR(VLOOKUP(TEXT(G14,"yyyymmdd")&"|1",'Project Tracker'!$F$2:$G$201,2,FALSE),"")&IFERROR(CHAR(10)&VLOOKUP(TEXT(G14,"yyyymmdd")&"|2",'Project Tracker'!$F$2:$G$201,2,FALSE),"")&IFERROR(CHAR(10)&VLOOKUP(TEXT(G14,"yyyymmdd")&"|3",'Project Tracker'!$F$2:$G$201,2,FALSE),"")&IF(COUNTIFS('Project Tracker'!$D$2:$D$201,G14,'Project Tracker'!$B$2:$B$201,"<>")>3,CHAR(10)&"+ "&(COUNTIFS('Project Tracker'!$D$2:$D$201,G14,'Project Tracker'!$B$2:$B$201,"<>")-3)&" more","")) | H15: =IF(H14="","",IFERROR(VLOOKUP(TEXT(H14,"yyyymmdd")&"|1",'Project Tracker'!$F$2:$G$201,2,FALSE),"")&IFERROR(CHAR(10)&VLOOKUP(TEXT(H14,"yyyymmdd")&"|2",'Project Tracker'!$F$2:$G$201,2,FALSE),"")&IFERROR(CHAR(10)&VLOOKUP(TEXT(H14,"yyyymmdd")&"|3",'Project Tracker'!$F$2:$G$201,2,FALSE),"")&IF(COUNTIFS('Project Tracker'!$D$2:$D$201,H14,'Project Tracker'!$B$2:$B$201,"<>")>3,CHAR(10)&"+ "&(COUNTIFS('Project Tracker'!$D$2:$D$201,H14,'Project Tracker'!$B$2:$B$201,"<>")-3)&" more",""))
A16: Legend / Notes
A17: Edit the Send Date on Project Tracker to move projects on the calendar. Blank dates will not appear.

Sheet February 2027 Calendar
A1: February 2027 Project Calendar
A3: Week | B3: Mon | C3: Tue | D3: Wed | E3: Thu | F3: Fri | G3: Sat | H3: Sun
A4: Week 1 | B4: 46419 | C4: 46420 | D4: 46421 | E4: 46422 | F4: 46423 | G4: 46424 | H4: 46425
B5: =IF(B4="","",IFERROR(VLOOKUP(TEXT(B4,"yyyymmdd")&"|1",'Project Tracker'!$F$2:$G$201,2,FALSE),"")&IFERROR(CHAR(10)&VLOOKUP(TEXT(B4,"yyyymmdd")&"|2",'Project Tracker'!$F$2:$G$201,2,FALSE),"")&IFERROR(CHAR(10)&VLOOKUP(TEXT(B4,"yyyymmdd")&"|3",'Project Tracker'!$F$2:$G$201,2,FALSE),"")&IF(COUNTIFS('Project Tracker'!$D$2:$D$201,B4,'Project Tracker'!$B$2:$B$201,"<>")>3,CHAR(10)&"+ "&(COUNTIFS('Project Tracker'!$D$2:$D$201,B4,'Project Tracker'!$B$2:$B$201,"<>")-3)&" more","")) | C5: =IF(C4="","",IFERROR(VLOOKUP(TEXT(C4,"yyyymmdd")&"|1",'Project Tracker'!$F$2:$G$201,2,FALSE),"")&IFERROR(CHAR(10)&VLOOKUP(TEXT(C4,"yyyymmdd")&"|2",'Project Tracker'!$F$2:$G$201,2,FALSE),"")&IFERROR(CHAR(10)&VLOOKUP(TEXT(C4,"yyyymmdd")&"|3",'Project Tracker'!$F$2:$G$201,2,FALSE),"")&IF(COUNTIFS('Project Tracker'!$D$2:$D$201,C4,'Project Tracker'!$B$2:$B$201,"<>")>3,CHAR(10)&"+ "&(COUNTIFS('Project Tracker'!$D$2:$D$201,C4,'Project Tracker'!$B$2:$B$201,"<>")-3)&" more","")) -> TEST | D5: =IF(D4="","",IFERROR(VLOOKUP(TEXT(D4,"yyyymmdd")&"|1",'Project Tracker'!$F$2:$G$201,2,FALSE),"")&IFERROR(CHAR(10)&VLOOKUP(TEXT(D4,"yyyymmdd")&"|2",'Project Tracker'!$F$2:$G$201,2,FALSE),"")&IFERROR(CHAR(10)&VLOOKUP(TEXT(D4,"yyyymmdd")&"|3",'Project Tracker'!$F$2:$G$201,2,FALSE),"")&IF(COUNTIFS('Project Tracker'!$D$2:$D$201,D4,'Project Tracker'!$B$2:$B$201,"<>")>3,CHAR(10)&"+ "&(COUNTIFS('Project Tracker'!$D$2:$D$201,D4,'Project Tracker'!$B$2:$B$201,"<>")-3)&" more","")) | E5: =IF(E4="","",IFERROR(VLOOKUP(TEXT(E4,"yyyymmdd")&"|1",'Project Tracker'!$F$2:$G$201,2,FALSE),"")&IFERROR(CHAR(10)&VLOOKUP(TEXT(E4,"yyyymmdd")&"|2",'Project Tracker'!$F$2:$G$201,2,FALSE),"")&IFERROR(CHAR(10)&VLOOKUP(TEXT(E4,"yyyymmdd")&"|3",'Project Tracker'!$F$2:$G$201,2,FALSE),"")&IF(COUNTIFS('Project Tracker'!$D$2:$D$201,E4,'Project Tracker'!$B$2:$B$201,"<>")>3,CHAR(10)&"+ "&(COUNTIFS('Project Tracker'!$D$2:$D$201,E4,'Project Tracker'!$B$2:$B$201,"<>")-3)&" more","")) | F5: =IF(F4="","",IFERROR(VLOOKUP(TEXT(F4,"yyyymmdd")&"|1",'Project Tracker'!$F$2:$G$201,2,FALSE),"")&IFERROR(CHAR(10)&VLOOKUP(TEXT(F4,"yyyymmdd")&"|2",'Project Tracker'!$F$2:$G$201,2,FALSE),"")&IFERROR(CHAR(10)&VLOOKUP(TEXT(F4,"yyyymmdd")&"|3",'Project Tracker'!$F$2:$G$201,2,FALSE),"")&IF(COUNTIFS('Project Tracker'!$D$2:$D$201,F4,'Project Tracker'!$B$2:$B$201,"<>")>3,CHAR(10)&"+ "&(COUNTIFS('Project Tracker'!$D$2:$D$201,F4,'Project Tracker'!$B$2:$B$201,"<>")-3)&" more","")) | G5: =IF(G4="","",IFERROR(VLOOKUP(TEXT(G4,"yyyymmdd")&"|1",'Project Tracker'!$F$2:$G$201,2,FALSE),"")&IFERROR(CHAR(10)&VLOOKUP(TEXT(G4,"yyyymmdd")&"|2",'Project Tracker'!$F$2:$G$201,2,FALSE),"")&IFERROR(CHAR(10)&VLOOKUP(TEXT(G4,"yyyymmdd")&"|3",'Project Tracker'!$F$2:$G$201,2,FALSE),"")&IF(COUNTIFS('Project Tracker'!$D$2:$D$201,G4,'Project Tracker'!$B$2:$B$201,"<>")>3,CHAR(10)&"+ "&(COUNTIFS('Project Tracker'!$D$2:$D$201,G4,'Project Tracker'!$B$2:$B$201,"<>")-3)&" more","")) | H5: =IF(H4="","",IFERROR(VLOOKUP(TEXT(H4,"yyyymmdd")&"|1",'Project Tracker'!$F$2:$G$201,2,FALSE),"")&IFERROR(CHAR(10)&VLOOKUP(TEXT(H4,"yyyymmdd")&"|2",'Project Tracker'!$F$2:$G$201,2,FALSE),"")&IFERROR(CHAR(10)&VLOOKUP(TEXT(H4,"yyyymmdd")&"|3",'Project Tracker'!$F$2:$G$201,2,FALSE),"")&IF(COUNTIFS('Project Tracker'!$D$2:$D$201,H4,'Project Tracker'!$B$2:$B$201,"<>")>3,CHAR(10)&"+ "&(COUNTIFS('Project Tracker'!$D$2:$D$201,H4,'Project Tracker'!$B$2:$B$201,"<>")-3)&" more",""))
A6: Week 2 | B6: 46426 | C6: 46427 | D6: 46428 | E6: 46429 | F6: 46430 | G6: 46431 | H6: 46432
B7: =IF(B6="","",IFERROR(VLOOKUP(TEXT(B6,"yyyymmdd")&"|1",'Project Tracker'!$F$2:$G$201,2,FALSE),"")&IFERROR(CHAR(10)&VLOOKUP(TEXT(B6,"yyyymmdd")&"|2",'Project Tracker'!$F$2:$G$201,2,FALSE),"")&IFERROR(CHAR(10)&VLOOKUP(TEXT(B6,"yyyymmdd")&"|3",'Project Tracker'!$F$2:$G$201,2,FALSE),"")&IF(COUNTIFS('Project Tracker'!$D$2:$D$201,B6,'Project Tracker'!$B$2:$B$201,"<>")>3,CHAR(10)&"+ "&(COUNTIFS('Project Tracker'!$D$2:$D$201,B6,'Project Tracker'!$B$2:$B$201,"<>")-3)&" more","")) | C7: =IF(C6="","",IFERROR(VLOOKUP(TEXT(C6,"yyyymmdd")&"|1",'Project Tracker'!$F$2:$G$201,2,FALSE),"")&IFERROR(CHAR(10)&VLOOKUP(TEXT(C6,"yyyymmdd")&"|2",'Project Tracker'!$F$2:$G$201,2,FALSE),"")&IFERROR(CHAR(10)&VLOOKUP(TEXT(C6,"yyyymmdd")&"|3",'Project Tracker'!$F$2:$G$201,2,FALSE),"")&IF(COUNTIFS('Project Tracker'!$D$2:$D$201,C6,'Project Tracker'!$B$2:$B$201,"<>")>3,CHAR(10)&"+ "&(COUNTIFS('Project Tracker'!$D$2:$D$201,C6,'Project Tracker'!$B$2:$B$201,"<>")-3)&" more","")) | D7: =IF(D6="","",IFERROR(VLOOKUP(TEXT(D6,"yyyymmdd")&"|1",'Project Tracker'!$F$2:$G$201,2,FALSE),"")&IFERROR(CHAR(10)&VLOOKUP(TEXT(D6,"yyyymmdd")&"|2",'Project Tracker'!$F$2:$G$201,2,FALSE),"")&IFERROR(CHAR(10)&VLOOKUP(TEXT(D6,"yyyymmdd")&"|3",'Project Tracker'!$F$2:$G$201,2,FALSE),"")&IF(COUNTIFS('Project Tracker'!$D$2:$D$201,D6,'Project Tracker'!$B$2:$B$201,"<>")>3,CHAR(10)&"+ "&(COUNTIFS('Project Tracker'!$D$2:$D$201,D6,'Project Tracker'!$B$2:$B$201,"<>")-3)&" more","")) | E7: =IF(E6="","",IFERROR(VLOOKUP(TEXT(E6,"yyyymmdd")&"|1",'Project Tracker'!$F$2:$G$201,2,FALSE),"")&IFERROR(CHAR(10)&VLOOKUP(TEXT(E6,"yyyymmdd")&"|2",'Project Tracker'!$F$2:$G$201,2,FALSE),"")&IFERROR(CHAR(10)&VLOOKUP(TEXT(E6,"yyyymmdd")&"|3",'Project Tracker'!$F$2:$G$201,2,FALSE),"")&IF(COUNTIFS('Project Tracker'!$D$2:$D$201,E6,'Project Tracker'!$B$2:$B$201,"<>")>3,CHAR(10)&"+ "&(COUNTIFS('Project Tracker'!$D$2:$D$201,E6,'Project Tracker'!$B$2:$B$201,"<>")-3)&" more","")) | F7: =IF(F6="","",IFERROR(VLOOKUP(TEXT(F6,"yyyymmdd")&"|1",'Project Tracker'!$F$2:$G$201,2,FALSE),"")&IFERROR(CHAR(10)&VLOOKUP(TEXT(F6,"yyyymmdd")&"|2",'Project Tracker'!$F$2:$G$201,2,FALSE),"")&IFERROR(CHAR(10)&VLOOKUP(TEXT(F6,"yyyymmdd")&"|3",'Project Tracker'!$F$2:$G$201,2,FALSE),"")&IF(COUNTIFS('Project Tracker'!$D$2:$D$201,F6,'Project Tracker'!$B$2:$B$201,"<>")>3,CHAR(10)&"+ "&(COUNTIFS('Project Tracker'!$D$2:$D$201,F6,'Project Tracker'!$B$2:$B$201,"<>")-3)&" more","")) | G7: =IF(G6="","",IFERROR(VLOOKUP(TEXT(G6,"yyyymmdd")&"|1",'Project Tracker'!$F$2:$G$201,2,FALSE),"")&IFERROR(CHAR(10)&VLOOKUP(TEXT(G6,"yyyymmdd")&"|2",'Project Tracker'!$F$2:$G$201,2,FALSE),"")&IFERROR(CHAR(10)&VLOOKUP(TEXT(G6,"yyyymmdd")&"|3",'Project Tracker'!$F$2:$G$201,2,FALSE),"")&IF(COUNTIFS('Project Tracker'!$D$2:$D$201,G6,'Project Tracker'!$B$2:$B$201,"<>")>3,CHAR(10)&"+ "&(COUNTIFS('Project Tracker'!$D$2:$D$201,G6,'Project Tracker'!$B$2:$B$201,"<>")-3)&" more","")) | H7: =IF(H6="","",IFERROR(VLOOKUP(TEXT(H6,"yyyymmdd")&"|1",'Project Tracker'!$F$2:$G$201,2,FALSE),"")&IFERROR(CHAR(10)&VLOOKUP(TEXT(H6,"yyyymmdd")&"|2",'Project Tracker'!$F$2:$G$201,2,FALSE),"")&IFERROR(CHAR(10)&VLOOKUP(TEXT(H6,"yyyymmdd")&"|3",'Project Tracker'!$F$2:$G$201,2,FALSE),"")&IF(COUNTIFS('Project Tracker'!$D$2:$D$201,H6,'Project Tracker'!$B$2:$B$201,"<>")>3,CHAR(10)&"+ "&(COUNTIFS('Project Tracker'!$D$2:$D$201,H6,'Project Tracker'!$B$2:$B$201,"<>")-3)&" more",""))
A8: Week 3 | B8: 46433 | C8: 46434 | D8: 46435 | E8: 46436 | F8: 46437 | G8: 46438 | H8: 46439
B9: =IF(B8="","",IFERROR(VLOOKUP(TEXT(B8,"yyyymmdd")&"|1",'Project Tracker'!$F$2:$G$201,2,FALSE),"")&IFERROR(CHAR(10)&VLOOKUP(TEXT(B8,"yyyymmdd")&"|2",'Project Tracker'!$F$2:$G$201,2,FALSE),"")&IFERROR(CHAR(10)&VLOOKUP(TEXT(B8,"yyyymmdd")&"|3",'Project Tracker'!$F$2:$G$201,2,FALSE),"")&IF(COUNTIFS('Project Tracker'!$D$2:$D$201,B8,'Project Tracker'!$B$2:$B$201,"<>")>3,CHAR(10)&"+ "&(COUNTIFS('Project Tracker'!$D$2:$D$201,B8,'Project Tracker'!$B$2:$B$201,"<>")-3)&" more","")) | C9: =IF(C8="","",IFERROR(VLOOKUP(TEXT(C8,"yyyymmdd")&"|1",'Project Tracker'!$F$2:$G$201,2,FALSE),"")&IFERROR(CHAR(10)&VLOOKUP(TEXT(C8,"yyyymmdd")&"|2",'Project Tracker'!$F$2:$G$201,2,FALSE),"")&IFERROR(CHAR(10)&VLOOKUP(TEXT(C8,"yyyymmdd")&"|3",'Project Tracker'!$F$2:$G$201,2,FALSE),"")&IF(COUNTIFS('Project Tracker'!$D$2:$D$201,C8,'Project Tracker'!$B$2:$B$201,"<>")>3,CHAR(10)&"+ "&(COUNTIFS('Project Tracker'!$D$2:$D$201,C8,'Project Tracker'!$B$2:$B$201,"<>")-3)&" more","")) | D9: =IF(D8="","",IFERROR(VLOOKUP(TEXT(D8,"yyyymmdd")&"|1",'Project Tracker'!$F$2:$G$201,2,FALSE),"")&IFERROR(CHAR(10)&VLOOKUP(TEXT(D8,"yyyymmdd")&"|2",'Project Tracker'!$F$2:$G$201,2,FALSE),"")&IFERROR(CHAR(10)&VLOOKUP(TEXT(D8,"yyyymmdd")&"|3",'Project Tracker'!$F$2:$G$201,2,FALSE),"")&IF(COUNTIFS('Project Tracker'!$D$2:$D$201,D8,'Project Tracker'!$B$2:$B$201,"<>")>3,CHAR(10)&"+ "&(COUNTIFS('Project Tracker'!$D$2:$D$201,D8,'Project Tracker'!$B$2:$B$201,"<>")-3)&" more","")) | E9: =IF(E8="","",IFERROR(VLOOKUP(TEXT(E8,"yyyymmdd")&"|1",'Project Tracker'!$F$2:$G$201,2,FALSE),"")&IFERROR(CHAR(10)&VLOOKUP(TEXT(E8,"yyyymmdd")&"|2",'Project Tracker'!$F$2:$G$201,2,FALSE),"")&IFERROR(CHAR(10)&VLOOKUP(TEXT(E8,"yyyymmdd")&"|3",'Project Tracker'!$F$2:$G$201,2,FALSE),"")&IF(COUNTIFS('Project Tracker'!$D$2:$D$201,E8,'Project Tracker'!$B$2:$B$201,"<>")>3,CHAR(10)&"+ "&(COUNTIFS('Project Tracker'!$D$2:$D$201,E8,'Project Tracker'!$B$2:$B$201,"<>")-3)&" more","")) | F9: =IF(F8="","",IFERROR(VLOOKUP(TEXT(F8,"yyyymmdd")&"|1",'Project Tracker'!$F$2:$G$201,2,FALSE),"")&IFERROR(CHAR(10)&VLOOKUP(TEXT(F8,"yyyymmdd")&"|2",'Project Tracker'!$F$2:$G$201,2,FALSE),"")&IFERROR(CHAR(10)&VLOOKUP(TEXT(F8,"yyyymmdd")&"|3",'Project Tracker'!$F$2:$G$201,2,FALSE),"")&IF(COUNTIFS('Project Tracker'!$D$2:$D$201,F8,'Project Tracker'!$B$2:$B$201,"<>")>3,CHAR(10)&"+ "&(COUNTIFS('Project Tracker'!$D$2:$D$201,F8,'Project Tracker'!$B$2:$B$201,"<>")-3)&" more","")) | G9: =IF(G8="","",IFERROR(VLOOKUP(TEXT(G8,"yyyymmdd")&"|1",'Project Tracker'!$F$2:$G$201,2,FALSE),"")&IFERROR(CHAR(10)&VLOOKUP(TEXT(G8,"yyyymmdd")&"|2",'Project Tracker'!$F$2:$G$201,2,FALSE),"")&IFERROR(CHAR(10)&VLOOKUP(TEXT(G8,"yyyymmdd")&"|3",'Project Tracker'!$F$2:$G$201,2,FALSE),"")&IF(COUNTIFS('Project Tracker'!$D$2:$D$201,G8,'Project Tracker'!$B$2:$B$201,"<>")>3,CHAR(10)&"+ "&(COUNTIFS('Project Tracker'!$D$2:$D$201,G8,'Project Tracker'!$B$2:$B$201,"<>")-3)&" more","")) | H9: =IF(H8="","",IFERROR(VLOOKUP(TEXT(H8,"yyyymmdd")&"|1",'Project Tracker'!$F$2:$G$201,2,FALSE),"")&IFERROR(CHAR(10)&VLOOKUP(TEXT(H8,"yyyymmdd")&"|2",'Project Tracker'!$F$2:$G$201,2,FALSE),"")&IFERROR(CHAR(10)&VLOOKUP(TEXT(H8,"yyyymmdd")&"|3",'Project Tracker'!$F$2:$G$201,2,FALSE),"")&IF(COUNTIFS('Project Tracker'!$D$2:$D$201,H8,'Project Tracker'!$B$2:$B$201,"<>")>3,CHAR(10)&"+ "&(COUNTIFS('Project Tracker'!$D$2:$D$201,H8,'Project Tracker'!$B$2:$B$201,"<>")-3)&" more",""))
A10: Week 4 | B10: 46440 | C10: 46441 | D10: 46442 | E10: 46443 | F10: 46444 | G10: 46445 | H10: 46446
B11: =IF(B10="","",IFERROR(VLOOKUP(TEXT(B10,"yyyymmdd")&"|1",'Project Tracker'!$F$2:$G$201,2,FALSE),"")&IFERROR(CHAR(10)&VLOOKUP(TEXT(B10,"yyyymmdd")&"|2",'Project Tracker'!$F$2:$G$201,2,FALSE),"")&IFERROR(CHAR(10)&VLOOKUP(TEXT(B10,"yyyymmdd")&"|3",'Project Tracker'!$F$2:$G$201,2,FALSE),"")&IF(COUNTIFS('Project Tracker'!$D$2:$D$201,B10,'Project Tracker'!$B$2:$B$201,"<>")>3,CHAR(10)&"+ "&(COUNTIFS('Project Tracker'!$D$2:$D$201,B10,'Project Tracker'!$B$2:$B$201,"<>")-3)&" more","")) | C11: =IF(C10="","",IFERROR(VLOOKUP(TEXT(C10,"yyyymmdd")&"|1",'Project Tracker'!$F$2:$G$201,2,FALSE),"")&IFERROR(CHAR(10)&VLOOKUP(TEXT(C10,"yyyymmdd")&"|2",'Project Tracker'!$F$2:$G$201,2,FALSE),"")&IFERROR(CHAR(10)&VLOOKUP(TEXT(C10,"yyyymmdd")&"|3",'Project Tracker'!$F$2:$G$201,2,FALSE),"")&IF(COUNTIFS('Project Tracker'!$D$2:$D$201,C10,'Project Tracker'!$B$2:$B$201,"<>")>3,CHAR(10)&"+ "&(COUNTIFS('Project Tracker'!$D$2:$D$201,C10,'Project Tracker'!$B$2:$B$201,"<>")-3)&" more","")) | D11: =IF(D10="","",IFERROR(VLOOKUP(TEXT(D10,"yyyymmdd")&"|1",'Project Tracker'!$F$2:$G$201,2,FALSE),"")&IFERROR(CHAR(10)&VLOOKUP(TEXT(D10,"yyyymmdd")&"|2",'Project Tracker'!$F$2:$G$201,2,FALSE),"")&IFERROR(CHAR(10)&VLOOKUP(TEXT(D10,"yyyymmdd")&"|3",'Project Tracker'!$F$2:$G$201,2,FALSE),"")&IF(COUNTIFS('Project Tracker'!$D$2:$D$201,D10,'Project Tracker'!$B$2:$B$201,"<>")>3,CHAR(10)&"+ "&(COUNTIFS('Project Tracker'!$D$2:$D$201,D10,'Project Tracker'!$B$2:$B$201,"<>")-3)&" more","")) | E11: =IF(E10="","",IFERROR(VLOOKUP(TEXT(E10,"yyyymmdd")&"|1",'Project Tracker'!$F$2:$G$201,2,FALSE),"")&IFERROR(CHAR(10)&VLOOKUP(TEXT(E10,"yyyymmdd")&"|2",'Project Tracker'!$F$2:$G$201,2,FALSE),"")&IFERROR(CHAR(10)&VLOOKUP(TEXT(E10,"yyyymmdd")&"|3",'Project Tracker'!$F$2:$G$201,2,FALSE),"")&IF(COUNTIFS('Project Tracker'!$D$2:$D$201,E10,'Project Tracker'!$B$2:$B$201,"<>")>3,CHAR(10)&"+ "&(COUNTIFS('Project Tracker'!$D$2:$D$201,E10,'Project Tracker'!$B$2:$B$201,"<>")-3)&" more","")) | F11: =IF(F10="","",IFERROR(VLOOKUP(TEXT(F10,"yyyymmdd")&"|1",'Project Tracker'!$F$2:$G$201,2,FALSE),"")&IFERROR(CHAR(10)&VLOOKUP(TEXT(F10,"yyyymmdd")&"|2",'Project Tracker'!$F$2:$G$201,2,FALSE),"")&IFERROR(CHAR(10)&VLOOKUP(TEXT(F10,"yyyymmdd")&"|3",'Project Tracker'!$F$2:$G$201,2,FALSE),"")&IF(COUNTIFS('Project Tracker'!$D$2:$D$201,F10,'Project Tracker'!$B$2:$B$201,"<>")>3,CHAR(10)&"+ "&(COUNTIFS('Project Tracker'!$D$2:$D$201,F10,'Project Tracker'!$B$2:$B$201,"<>")-3)&" more","")) | G11: =IF(G10="","",IFERROR(VLOOKUP(TEXT(G10,"yyyymmdd")&"|1",'Project Tracker'!$F$2:$G$201,2,FALSE),"")&IFERROR(CHAR(10)&VLOOKUP(TEXT(G10,"yyyymmdd")&"|2",'Project Tracker'!$F$2:$G$201,2,FALSE),"")&IFERROR(CHAR(10)&VLOOKUP(TEXT(G10,"yyyymmdd")&"|3",'Project Tracker'!$F$2:$G$201,2,FALSE),"")&IF(COUNTIFS('Project Tracker'!$D$2:$D$201,G10,'Project Tracker'!$B$2:$B$201,"<>")>3,CHAR(10)&"+ "&(COUNTIFS('Project Tracker'!$D$2:$D$201,G10,'Project Tracker'!$B$2:$B$201,"<>")-3)&" more","")) | H11: =IF(H10="","",IFERROR(VLOOKUP(TEXT(H10,"yyyymmdd")&"|1",'Project Tracker'!$F$2:$G$201,2,FALSE),"")&IFERROR(CHAR(10)&VLOOKUP(TEXT(H10,"yyyymmdd")&"|2",'Project Tracker'!$F$2:$G$201,2,FALSE),"")&IFERROR(CHAR(10)&VLOOKUP(TEXT(H10,"yyyymmdd")&"|3",'Project Tracker'!$F$2:$G$201,2,FALSE),"")&IF(COUNTIFS('Project Tracker'!$D$2:$D$201,H10,'Project Tracker'!$B$2:$B$201,"<>")>3,CHAR(10)&"+ "&(COUNTIFS('Project Tracker'!$D$2:$D$201,H10,'Project Tracker'!$B$2:$B$201,"<>")-3)&" more",""))
B13: =IF(B12="","",IFERROR(VLOOKUP(TEXT(B12,"yyyymmdd")&"|1",'Project Tracker'!$F$2:$G$201,2,FALSE),"")&IFERROR(CHAR(10)&VLOOKUP(TEXT(B12,"yyyymmdd")&"|2",'Project Tracker'!$F$2:$G$201,2,FALSE),"")&IFERROR(CHAR(10)&VLOOKUP(TEXT(B12,"yyyymmdd")&"|3",'Project Tracker'!$F$2:$G$201,2,FALSE),"")&IF(COUNTIFS('Project Tracker'!$D$2:$D$201,B12,'Project Tracker'!$B$2:$B$201,"<>")>3,CHAR(10)&"+ "&(COUNTIFS('Project Tracker'!$D$2:$D$201,B12,'Project Tracker'!$B$2:$B$201,"<>")-3)&" more","")) | C13: =IF(C12="","",IFERROR(VLOOKUP(TEXT(C12,"yyyymmdd")&"|1",'Project Tracker'!$F$2:$G$201,2,FALSE),"")&IFERROR(CHAR(10)&VLOOKUP(TEXT(C12,"yyyymmdd")&"|2",'Project Tracker'!$F$2:$G$201,2,FALSE),"")&IFERROR(CHAR(10)&VLOOKUP(TEXT(C12,"yyyymmdd")&"|3",'Project Tracker'!$F$2:$G$201,2,FALSE),"")&IF(COUNTIFS('Project Tracker'!$D$2:$D$201,C12,'Project Tracker'!$B$2:$B$201,"<>")>3,CHAR(10)&"+ "&(COUNTIFS('Project Tracker'!$D$2:$D$201,C12,'Project Tracker'!$B$2:$B$201,"<>")-3)&" more","")) | D13: =IF(D12="","",IFERROR(VLOOKUP(TEXT(D12,"yyyymmdd")&"|1",'Project Tracker'!$F$2:$G$201,2,FALSE),"")&IFERROR(CHAR(10)&VLOOKUP(TEXT(D12,"yyyymmdd")&"|2",'Project Tracker'!$F$2:$G$201,2,FALSE),"")&IFERROR(CHAR(10)&VLOOKUP(TEXT(D12,"yyyymmdd")&"|3",'Project Tracker'!$F$2:$G$201,2,FALSE),"")&IF(COUNTIFS('Project Tracker'!$D$2:$D$201,D12,'Project Tracker'!$B$2:$B$201,"<>")>3,CHAR(10)&"+ "&(COUNTIFS('Project Tracker'!$D$2:$D$201,D12,'Project Tracker'!$B$2:$B$201,"<>")-3)&" more","")) | E13: =IF(E12="","",IFERROR(VLOOKUP(TEXT(E12,"yyyymmdd")&"|1",'Project Tracker'!$F$2:$G$201,2,FALSE),"")&IFERROR(CHAR(10)&VLOOKUP(TEXT(E12,"yyyymmdd")&"|2",'Project Tracker'!$F$2:$G$201,2,FALSE),"")&IFERROR(CHAR(10)&VLOOKUP(TEXT(E12,"yyyymmdd")&"|3",'Project Tracker'!$F$2:$G$201,2,FALSE),"")&IF(COUNTIFS('Project Tracker'!$D$2:$D$201,E12,'Project Tracker'!$B$2:$B$201,"<>")>3,CHAR(10)&"+ "&(COUNTIFS('Project Tracker'!$D$2:$D$201,E12,'Project Tracker'!$B$2:$B$201,"<>")-3)&" more","")) | F13: =IF(F12="","",IFERROR(VLOOKUP(TEXT(F12,"yyyymmdd")&"|1",'Project Tracker'!$F$2:$G$201,2,FALSE),"")&IFERROR(CHAR(10)&VLOOKUP(TEXT(F12,"yyyymmdd")&"|2",'Project Tracker'!$F$2:$G$201,2,FALSE),"")&IFERROR(CHAR(10)&VLOOKUP(TEXT(F12,"yyyymmdd")&"|3",'Project Tracker'!$F$2:$G$201,2,FALSE),"")&IF(COUNTIFS('Project Tracker'!$D$2:$D$201,F12,'Project Tracker'!$B$2:$B$201,"<>")>3,CHAR(10)&"+ "&(COUNTIFS('Project Tracker'!$D$2:$D$201,F12,'Project Tracker'!$B$2:$B$201,"<>")-3)&" more","")) | G13: =IF(G12="","",IFERROR(VLOOKUP(TEXT(G12,"yyyymmdd")&"|1",'Project Tracker'!$F$2:$G$201,2,FALSE),"")&IFERROR(CHAR(10)&VLOOKUP(TEXT(G12,"yyyymmdd")&"|2",'Project Tracker'!$F$2:$G$201,2,FALSE),"")&IFERROR(CHAR(10)&VLOOKUP(TEXT(G12,"yyyymmdd")&"|3",'Project Tracker'!$F$2:$G$201,2,FALSE),"")&IF(COUNTIFS('Project Tracker'!$D$2:$D$201,G12,'Project Tracker'!$B$2:$B$201,"<>")>3,CHAR(10)&"+ "&(COUNTIFS('Project Tracker'!$D$2:$D$201,G12,'Project Tracker'!$B$2:$B$201,"<>")-3)&" more","")) | H13: =IF(H12="","",IFERROR(VLOOKUP(TEXT(H12,"yyyymmdd")&"|1",'Project Tracker'!$F$2:$G$201,2,FALSE),"")&IFERROR(CHAR(10)&VLOOKUP(TEXT(H12,"yyyymmdd")&"|2",'Project Tracker'!$F$2:$G$201,2,FALSE),"")&IFERROR(CHAR(10)&VLOOKUP(TEXT(H12,"yyyymmdd")&"|3",'Project Tracker'!$F$2:$G$201,2,FALSE),"")&IF(COUNTIFS('Project Tracker'!$D$2:$D$201,H12,'Project Tracker'!$B$2:$B$201,"<>")>3,CHAR(10)&"+ "&(COUNTIFS('Project Tracker'!$D$2:$D$201,H12,'Project Tracker'!$B$2:$B$201,"<>")-3)&" more",""))
B15: =IF(B14="","",IFERROR(VLOOKUP(TEXT(B14,"yyyymmdd")&"|1",'Project Tracker'!$F$2:$G$201,2,FALSE),"")&IFERROR(CHAR(10)&VLOOKUP(TEXT(B14,"yyyymmdd")&"|2",'Project Tracker'!$F$2:$G$201,2,FALSE),"")&IFERROR(CHAR(10)&VLOOKUP(TEXT(B14,"yyyymmdd")&"|3",'Project Tracker'!$F$2:$G$201,2,FALSE),"")&IF(COUNTIFS('Project Tracker'!$D$2:$D$201,B14,'Project Tracker'!$B$2:$B$201,"<>")>3,CHAR(10)&"+ "&(COUNTIFS('Project Tracker'!$D$2:$D$201,B14,'Project Tracker'!$B$2:$B$201,"<>")-3)&" more","")) | C15: =IF(C14="","",IFERROR(VLOOKUP(TEXT(C14,"yyyymmdd")&"|1",'Project Tracker'!$F$2:$G$201,2,FALSE),"")&IFERROR(CHAR(10)&VLOOKUP(TEXT(C14,"yyyymmdd")&"|2",'Project Tracker'!$F$2:$G$201,2,FALSE),"")&IFERROR(CHAR(10)&VLOOKUP(TEXT(C14,"yyyymmdd")&"|3",'Project Tracker'!$F$2:$G$201,2,FALSE),"")&IF(COUNTIFS('Project Tracker'!$D$2:$D$201,C14,'Project Tracker'!$B$2:$B$201,"<>")>3,CHAR(10)&"+ "&(COUNTIFS('Project Tracker'!$D$2:$D$201,C14,'Project Tracker'!$B$2:$B$201,"<>")-3)&" more","")) | D15: =IF(D14="","",IFERROR(VLOOKUP(TEXT(D14,"yyyymmdd")&"|1",'Project Tracker'!$F$2:$G$201,2,FALSE),"")&IFERROR(CHAR(10)&VLOOKUP(TEXT(D14,"yyyymmdd")&"|2",'Project Tracker'!$F$2:$G$201,2,FALSE),"")&IFERROR(CHAR(10)&VLOOKUP(TEXT(D14,"yyyymmdd")&"|3",'Project Tracker'!$F$2:$G$201,2,FALSE),"")&IF(COUNTIFS('Project Tracker'!$D$2:$D$201,D14,'Project Tracker'!$B$2:$B$201,"<>")>3,CHAR(10)&"+ "&(COUNTIFS('Project Tracker'!$D$2:$D$201,D14,'Project Tracker'!$B$2:$B$201,"<>")-3)&" more","")) | E15: =IF(E14="","",IFERROR(VLOOKUP(TEXT(E14,"yyyymmdd")&"|1",'Project Tracker'!$F$2:$G$201,2,FALSE),"")&IFERROR(CHAR(10)&VLOOKUP(TEXT(E14,"yyyymmdd")&"|2",'Project Tracker'!$F$2:$G$201,2,FALSE),"")&IFERROR(CHAR(10)&VLOOKUP(TEXT(E14,"yyyymmdd")&"|3",'Project Tracker'!$F$2:$G$201,2,FALSE),"")&IF(COUNTIFS('Project Tracker'!$D$2:$D$201,E14,'Project Tracker'!$B$2:$B$201,"<>")>3,CHAR(10)&"+ "&(COUNTIFS('Project Tracker'!$D$2:$D$201,E14,'Project Tracker'!$B$2:$B$201,"<>")-3)&" more","")) | F15: =IF(F14="","",IFERROR(VLOOKUP(TEXT(F14,"yyyymmdd")&"|1",'Project Tracker'!$F$2:$G$201,2,FALSE),"")&IFERROR(CHAR(10)&VLOOKUP(TEXT(F14,"yyyymmdd")&"|2",'Project Tracker'!$F$2:$G$201,2,FALSE),"")&IFERROR(CHAR(10)&VLOOKUP(TEXT(F14,"yyyymmdd")&"|3",'Project Tracker'!$F$2:$G$201,2,FALSE),"")&IF(COUNTIFS('Project Tracker'!$D$2:$D$201,F14,'Project Tracker'!$B$2:$B$201,"<>")>3,CHAR(10)&"+ "&(COUNTIFS('Project Tracker'!$D$2:$D$201,F14,'Project Tracker'!$B$2:$B$201,"<>")-3)&" more","")) | G15: =IF(G14="","",IFERROR(VLOOKUP(TEXT(G14,"yyyymmdd")&"|1",'Project Tracker'!$F$2:$G$201,2,FALSE),"")&IFERROR(CHAR(10)&VLOOKUP(TEXT(G14,"yyyymmdd")&"|2",'Project Tracker'!$F$2:$G$201,2,FALSE),"")&IFERROR(CHAR(10)&VLOOKUP(TEXT(G14,"yyyymmdd")&"|3",'Project Tracker'!$F$2:$G$201,2,FALSE),"")&IF(COUNTIFS('Project Tracker'!$D$2:$D$201,G14,'Project Tracker'!$B$2:$B$201,"<>")>3,CHAR(10)&"+ "&(COUNTIFS('Project Tracker'!$D$2:$D$201,G14,'Project Tracker'!$B$2:$B$201,"<>")-3)&" more","")) | H15: =IF(H14="","",IFERROR(VLOOKUP(TEXT(H14,"yyyymmdd")&"|1",'Project Tracker'!$F$2:$G$201,2,FALSE),"")&IFERROR(CHAR(10)&VLOOKUP(TEXT(H14,"yyyymmdd")&"|2",'Project Tracker'!$F$2:$G$201,2,FALSE),"")&IFERROR(CHAR(10)&VLOOKUP(TEXT(H14,"yyyymmdd")&"|3",'Project Tracker'!$F$2:$G$201,2,FALSE),"")&IF(COUNTIFS('Project Tracker'!$D$2:$D$201,H14,'Project Tracker'!$B$2:$B$201,"<>")>3,CHAR(10)&"+ "&(COUNTIFS('Project Tracker'!$D$2:$D$201,H14,'Project Tracker'!$B$2:$B$201,"<>")-3)&" more",""))
A16: Legend / Notes
A17: Edit the Send Date on Project Tracker to move projects on the calendar. Blank dates will not appear.

Sheet March 2027 Calendar
A1: March 2027 Project Calendar
A3: Week | B3: Mon | C3: Tue | D3: Wed | E3: Thu | F3: Fri | G3: Sat | H3: Sun
A4: Week 1 | B4: 46447 | C4: 46448 | D4: 46449 | E4: 46450 | F4: 46451 | G4: 46452 | H4: 46453
B5: =IF(B4="","",IFERROR(VLOOKUP(TEXT(B4,"yyyymmdd")&"|1",'Project Tracker'!$F$2:$G$201,2,FALSE),"")&IFERROR(CHAR(10)&VLOOKUP(TEXT(B4,"yyyymmdd")&"|2",'Project Tracker'!$F$2:$G$201,2,FALSE),"")&IFERROR(CHAR(10)&VLOOKUP(TEXT(B4,"yyyymmdd")&"|3",'Project Tracker'!$F$2:$G$201,2,FALSE),"")&IF(COUNTIFS('Project Tracker'!$D$2:$D$201,B4,'Project Tracker'!$B$2:$B$201,"<>")>3,CHAR(10)&"+ "&(COUNTIFS('Project Tracker'!$D$2:$D$201,B4,'Project Tracker'!$B$2:$B$201,"<>")-3)&" more","")) | C5: =IF(C4="","",IFERROR(VLOOKUP(TEXT(C4,"yyyymmdd")&"|1",'Project Tracker'!$F$2:$G$201,2,FALSE),"")&IFERROR(CHAR(10)&VLOOKUP(TEXT(C4,"yyyymmdd")&"|2",'Project Tracker'!$F$2:$G$201,2,FALSE),"")&IFERROR(CHAR(10)&VLOOKUP(TEXT(C4,"yyyymmdd")&"|3",'Project Tracker'!$F$2:$G$201,2,FALSE),"")&IF(COUNTIFS('Project Tracker'!$D$2:$D$201,C4,'Project Tracker'!$B$2:$B$201,"<>")>3,CHAR(10)&"+ "&(COUNTIFS('Project Tracker'!$D$2:$D$201,C4,'Project Tracker'!$B$2:$B$201,"<>")-3)&" more","")) | D5: =IF(D4="","",IFERROR(VLOOKUP(TEXT(D4,"yyyymmdd")&"|1",'Project Tracker'!$F$2:$G$201,2,FALSE),"")&IFERROR(CHAR(10)&VLOOKUP(TEXT(D4,"yyyymmdd")&"|2",'Project Tracker'!$F$2:$G$201,2,FALSE),"")&IFERROR(CHAR(10)&VLOOKUP(TEXT(D4,"yyyymmdd")&"|3",'Project Tracker'!$F$2:$G$201,2,FALSE),"")&IF(COUNTIFS('Project Tracker'!$D$2:$D$201,D4,'Project Tracker'!$B$2:$B$201,"<>")>3,CHAR(10)&"+ "&(COUNTIFS('Project Tracker'!$D$2:$D$201,D4,'Project Tracker'!$B$2:$B$201,"<>")-3)&" more","")) -> TEST | E5: =IF(E4="","",IFERROR(VLOOKUP(TEXT(E4,"yyyymmdd")&"|1",'Project Tracker'!$F$2:$G$201,2,FALSE),"")&IFERROR(CHAR(10)&VLOOKUP(TEXT(E4,"yyyymmdd")&"|2",'Project Tracker'!$F$2:$G$201,2,FALSE),"")&IFERROR(CHAR(10)&VLOOKUP(TEXT(E4,"yyyymmdd")&"|3",'Project Tracker'!$F$2:$G$201,2,FALSE),"")&IF(COUNTIFS('Project Tracker'!$D$2:$D$201,E4,'Project Tracker'!$B$2:$B$201,"<>")>3,CHAR(10)&"+ "&(COUNTIFS('Project Tracker'!$D$2:$D$201,E4,'Project Tracker'!$B$2:$B$201,"<>")-3)&" more","")) | F5: =IF(F4="","",IFERROR(VLOOKUP(TEXT(F4,"yyyymmdd")&"|1",'Project Tracker'!$F$2:$G$201,2,FALSE),"")&IFERROR(CHAR(10)&VLOOKUP(TEXT(F4,"yyyymmdd")&"|2",'Project Tracker'!$F$2:$G$201,2,FALSE),"")&IFERROR(CHAR(10)&VLOOKUP(TEXT(F4,"yyyymmdd")&"|3",'Project Tracker'!$F$2:$G$201,2,FALSE),"")&IF(COUNTIFS('Project Tracker'!$D$2:$D$201,F4,'Project Tracker'!$B$2:$B$201,"<>")>3,CHAR(10)&"+ "&(COUNTIFS('Project Tracker'!$D$2:$D$201,F4,'Project Tracker'!$B$2:$B$201,"<>")-3)&" more","")) | G5: =IF(G4="","",IFERROR(VLOOKUP(TEXT(G4,"yyyymmdd")&"|1",'Project Tracker'!$F$2:$G$201,2,FALSE),"")&IFERROR(CHAR(10)&VLOOKUP(TEXT(G4,"yyyymmdd")&"|2",'Project Tracker'!$F$2:$G$201,2,FALSE),"")&IFERROR(CHAR(10)&VLOOKUP(TEXT(G4,"yyyymmdd")&"|3",'Project Tracker'!$F$2:$G$201,2,FALSE),"")&IF(COUNTIFS('Project Tracker'!$D$2:$D$201,G4,'Project Tracker'!$B$2:$B$201,"<>")>3,CHAR(10)&"+ "&(COUNTIFS('Project Tracker'!$D$2:$D$201,G4,'Project Tracker'!$B$2:$B$201,"<>")-3)&" more","")) | H5: =IF(H4="","",IFERROR(VLOOKUP(TEXT(H4,"yyyymmdd")&"|1",'Project Tracker'!$F$2:$G$201,2,FALSE),"")&IFERROR(CHAR(10)&VLOOKUP(TEXT(H4,"yyyymmdd")&"|2",'Project Tracker'!$F$2:$G$201,2,FALSE),"")&IFERROR(CHAR(10)&VLOOKUP(TEXT(H4,"yyyymmdd")&"|3",'Project Tracker'!$F$2:$G$201,2,FALSE),"")&IF(COUNTIFS('Project Tracker'!$D$2:$D$201,H4,'Project Tracker'!$B$2:$B$201,"<>")>3,CHAR(10)&"+ "&(COUNTIFS('Project Tracker'!$D$2:$D$201,H4,'Project Tracker'!$B$2:$B$201,"<>")-3)&" more",""))
A6: Week 2 | B6: 46454 | C6: 46455 | D6: 46456 | E6: 46457 | F6: 46458 | G6: 46459 | H6: 46460
B7: =IF(B6="","",IFERROR(VLOOKUP(TEXT(B6,"yyyymmdd")&"|1",'Project Tracker'!$F$2:$G$201,2,FALSE),"")&IFERROR(CHAR(10)&VLOOKUP(TEXT(B6,"yyyymmdd")&"|2",'Project Tracker'!$F$2:$G$201,2,FALSE),"")&IFERROR(CHAR(10)&VLOOKUP(TEXT(B6,"yyyymmdd")&"|3",'Project Tracker'!$F$2:$G$201,2,FALSE),"")&IF(COUNTIFS('Project Tracker'!$D$2:$D$201,B6,'Project Tracker'!$B$2:$B$201,"<>")>3,CHAR(10)&"+ "&(COUNTIFS('Project Tracker'!$D$2:$D$201,B6,'Project Tracker'!$B$2:$B$201,"<>")-3)&" more","")) | C7: =IF(C6="","",IFERROR(VLOOKUP(TEXT(C6,"yyyymmdd")&"|1",'Project Tracker'!$F$2:$G$201,2,FALSE),"")&IFERROR(CHAR(10)&VLOOKUP(TEXT(C6,"yyyymmdd")&"|2",'Project Tracker'!$F$2:$G$201,2,FALSE),"")&IFERROR(CHAR(10)&VLOOKUP(TEXT(C6,"yyyymmdd")&"|3",'Project Tracker'!$F$2:$G$201,2,FALSE),"")&IF(COUNTIFS('Project Tracker'!$D$2:$D$201,C6,'Project Tracker'!$B$2:$B$201,"<>")>3,CHAR(10)&"+ "&(COUNTIFS('Project Tracker'!$D$2:$D$201,C6,'Project Tracker'!$B$2:$B$201,"<>")-3)&" more","")) | D7: =IF(D6="","",IFERROR(VLOOKUP(TEXT(D6,"yyyymmdd")&"|1",'Project Tracker'!$F$2:$G$201,2,FALSE),"")&IFERROR(CHAR(10)&VLOOKUP(TEXT(D6,"yyyymmdd")&"|2",'Project Tracker'!$F$2:$G$201,2,FALSE),"")&IFERROR(CHAR(10)&VLOOKUP(TEXT(D6,"yyyymmdd")&"|3",'Project Tracker'!$F$2:$G$201,2,FALSE),"")&IF(COUNTIFS('Project Tracker'!$D$2:$D$201,D6,'Project Tracker'!$B$2:$B$201,"<>")>3,CHAR(10)&"+ "&(COUNTIFS('Project Tracker'!$D$2:$D$201,D6,'Project Tracker'!$B$2:$B$201,"<>")-3)&" more","")) | E7: =IF(E6="","",IFERROR(VLOOKUP(TEXT(E6,"yyyymmdd")&"|1",'Project Tracker'!$F$2:$G$201,2,FALSE),"")&IFERROR(CHAR(10)&VLOOKUP(TEXT(E6,"yyyymmdd")&"|2",'Project Tracker'!$F$2:$G$201,2,FALSE),"")&IFERROR(CHAR(10)&VLOOKUP(TEXT(E6,"yyyymmdd")&"|3",'Project Tracker'!$F$2:$G$201,2,FALSE),"")&IF(COUNTIFS('Project Tracker'!$D$2:$D$201,E6,'Project Tracker'!$B$2:$B$201,"<>")>3,CHAR(10)&"+ "&(COUNTIFS('Project Tracker'!$D$2:$D$201,E6,'Project Tracker'!$B$2:$B$201,"<>")-3)&" more","")) | F7: =IF(F6="","",IFERROR(VLOOKUP(TEXT(F6,"yyyymmdd")&"|1",'Project Tracker'!$F$2:$G$201,2,FALSE),"")&IFERROR(CHAR(10)&VLOOKUP(TEXT(F6,"yyyymmdd")&"|2",'Project Tracker'!$F$2:$G$201,2,FALSE),"")&IFERROR(CHAR(10)&VLOOKUP(TEXT(F6,"yyyymmdd")&"|3",'Project Tracker'!$F$2:$G$201,2,FALSE),"")&IF(COUNTIFS('Project Tracker'!$D$2:$D$201,F6,'Project Tracker'!$B$2:$B$201,"<>")>3,CHAR(10)&"+ "&(COUNTIFS('Project Tracker'!$D$2:$D$201,F6,'Project Tracker'!$B$2:$B$201,"<>")-3)&" more","")) | G7: =IF(G6="","",IFERROR(VLOOKUP(TEXT(G6,"yyyymmdd")&"|1",'Project Tracker'!$F$2:$G$201,2,FALSE),"")&IFERROR(CHAR(10)&VLOOKUP(TEXT(G6,"yyyymmdd")&"|2",'Project Tracker'!$F$2:$G$201,2,FALSE),"")&IFERROR(CHAR(10)&VLOOKUP(TEXT(G6,"yyyymmdd")&"|3",'Project Tracker'!$F$2:$G$201,2,FALSE),"")&IF(COUNTIFS('Project Tracker'!$D$2:$D$201,G6,'Project Tracker'!$B$2:$B$201,"<>")>3,CHAR(10)&"+ "&(COUNTIFS('Project Tracker'!$D$2:$D$201,G6,'Project Tracker'!$B$2:$B$201,"<>")-3)&" more","")) | H7: =IF(H6="","",IFERROR(VLOOKUP(TEXT(H6,"yyyymmdd")&"|1",'Project Tracker'!$F$2:$G$201,2,FALSE),"")&IFERROR(CHAR(10)&VLOOKUP(TEXT(H6,"yyyymmdd")&"|2",'Project Tracker'!$F$2:$G$201,2,FALSE),"")&IFERROR(CHAR(10)&VLOOKUP(TEXT(H6,"yyyymmdd")&"|3",'Project Tracker'!$F$2:$G$201,2,FALSE),"")&IF(COUNTIFS('Project Tracker'!$D$2:$D$201,H6,'Project Tracker'!$B$2:$B$201,"<>")>3,CHAR(10)&"+ "&(COUNTIFS('Project Tracker'!$D$2:$D$201,H6,'Project Tracker'!$B$2:$B$201,"<>")-3)&" more",""))
A8: Week 3 | B8: 46461 | C8: 46462 | D8: 46463 | E8: 46464 | F8: 46465 | G8: 46466 | H8: 46467
